<?xml version="1.0" ?>
<!-- =================================================================================== -->
<!-- |    This document was autogenerated by xacro from robot.urdf.xacro               | -->
<!-- |    EDITING THIS FILE BY HAND IS NOT RECOMMENDED                                 | -->
<!-- =================================================================================== -->
<robot name="talos" xmlns:xacro="http://www.ros.org/wiki/xacro">
  <material name="white">
    <color rgba="1.0 1.0 1.0 1.0"/>
  </material>
  <!-- these contain macros for their respective robot part -->
  <link name="base_link">
    <visual>
      <origin rpy="0 0 3.14159265359" xyz="0.311325 0.311325 0"/>
      <geometry>
        <mesh filename="package://talos_description/meshes/base/base_link.stl" scale="0.001 0.001 0.001"/>
      </geometry>
      <material name="white"/>
    </visual>
    <collision>
      <origin rpy="0 0 0" xyz="0 0 0.116085"/>
      <geometry>
        <box size="0.62265 0.62265 0.37817"/>
      </geometry>
    </collision>
    <inertial>
      <mass value="8.2"/>
      <inertia ixx="0.362648807123" ixy="0.0" ixz="0.0" iyy="0.52984713075" iyz="0.0" izz="0.362648807123"/>
    </inertial>
  </link>
  <link name="fl_caster_wheel_link">
    <mass value="1.2"/>
    <inertial>
      <mass value="1.2"/>
      <inertia ixx="0.0001431125" ixy="0.0" ixz="0.0" iyy="0.00024378125" iyz="0.0" izz="0.00024378125"/>
    </inertial>
    <visual>
      <origin rpy="0 -1.57079632679 0" xyz="0 0 0"/>
      <geometry>
        <cylinder length="0.02675" radius="0.0415"/>
        <!--<mesh filename="package://talos_description/meshes/wheel/caster_wheel.stl" scale="${scale} ${scale} ${scale}" />-->
      </geometry>
      <material name="white"/>
    </visual>
    <collision>
      <origin rpy="0 -1.57079632679 0" xyz="0 0 0"/>
      <geometry>
        <cylinder length="0.02675" radius="0.0415"/>
      </geometry>
    </collision>
  </link>
  <link name="fl_caster_link">
    <mass value="1.2"/>
    <inertial>
      <mass value="1.2"/>
      <inertia ixx="0.0020326265" ixy="0.0" ixz="0.0" iyy="0.00093223997" iyz="0.0" izz="0.00188764805"/>
    </inertial>
    <visual>
      <origin rpy="0 0 -1.57079632679" xyz="-0.03137 -0.0206624 -0.080437 "/>
      <geometry>
        <mesh filename="package://talos_description/meshes/wheel/caster.stl" scale="0.001 0.001 0.001"/>
      </geometry>
      <material name="white"/>
    </visual>
    <collision>
      <origin rpy="0 0 0" xyz="0 -0.0087 -0.019322"/>
      <geometry>
        <box size="0.06274 0.07339 0.12223"/>
      </geometry>
    </collision>
  </link>
  <joint name="fl_base_link_to_caster" type="continuous">
    <axis rpy="0 0 0" xyz="0 0 1"/>
    <origin rpy="0 0 0" xyz="0.2175 0.21745 0"/>
    <child link="fl_caster_link"/>
    <parent link="base_link"/>
  </joint>
  <joint name="fl_caster_to_wheel" type="continuous">
    <origin rpy="0 0 0" xyz="0 -0.0293624 -0.071437"/>
    <axis rpy="0 0 0" xyz="1 0 0"/>
    <limit effort="100" velocity="100"/>
    <joint_properties damping="0.0" friction="0.0"/>
    <child link="fl_caster_wheel_link"/>
    <parent link="fl_caster_link"/>
  </joint>
  <gazebo reference="fl_caster_wheel_link">
    <!-- <selfCollide>true</selfCollide> -->
    <mu1 value="0.0"/>
    <mu2 value="0.0"/>
    <!-- <kp value="100000.0" />
	             <kd value="1.0" /> -->
  </gazebo>
  <gazebo reference="fl_caster_link">
    <!-- <selfCollide>true</selfCollide> -->
    <mu1 value="0.0"/>
    <mu2 value="0.0"/>
    <!-- <kp value="100000.0" />
	             <kd value="1.0" /> -->
  </gazebo>
  <link name="fr_caster_wheel_link">
    <mass value="1.2"/>
    <inertial>
      <mass value="1.2"/>
      <inertia ixx="0.0001431125" ixy="0.0" ixz="0.0" iyy="0.00024378125" iyz="0.0" izz="0.00024378125"/>
    </inertial>
    <visual>
      <origin rpy="0 -1.57079632679 0" xyz="0 0 0"/>
      <geometry>
        <cylinder length="0.02675" radius="0.0415"/>
        <!--<mesh filename="package://talos_description/meshes/wheel/caster_wheel.stl" scale="${scale} ${scale} ${scale}" />-->
      </geometry>
      <material name="white"/>
    </visual>
    <collision>
      <origin rpy="0 -1.57079632679 0" xyz="0 0 0"/>
      <geometry>
        <cylinder length="0.02675" radius="0.0415"/>
      </geometry>
    </collision>
  </link>
  <link name="fr_caster_link">
    <mass value="1.2"/>
    <inertial>
      <mass value="1.2"/>
      <inertia ixx="0.0020326265" ixy="0.0" ixz="0.0" iyy="0.00093223997" iyz="0.0" izz="0.00188764805"/>
    </inertial>
    <visual>
      <origin rpy="0 0 -1.57079632679" xyz="-0.03137 -0.0206624 -0.080437 "/>
      <geometry>
        <mesh filename="package://talos_description/meshes/wheel/caster.stl" scale="0.001 0.001 0.001"/>
      </geometry>
      <material name="white"/>
    </visual>
    <collision>
      <origin rpy="0 0 0" xyz="0 -0.0087 -0.019322"/>
      <geometry>
        <box size="0.06274 0.07339 0.12223"/>
      </geometry>
    </collision>
  </link>
  <joint name="fr_base_link_to_caster" type="continuous">
    <axis rpy="0 0 0" xyz="0 0 1"/>
    <origin rpy="0 0 0" xyz="-0.2175 0.21745 0"/>
    <child link="fr_caster_link"/>
    <parent link="base_link"/>
  </joint>
  <joint name="fr_caster_to_wheel" type="continuous">
    <origin rpy="0 0 0" xyz="0 -0.0293624 -0.071437"/>
    <axis rpy="0 0 0" xyz="1 0 0"/>
    <limit effort="100" velocity="100"/>
    <joint_properties damping="0.0" friction="0.0"/>
    <child link="fr_caster_wheel_link"/>
    <parent link="fr_caster_link"/>
  </joint>
  <gazebo reference="fr_caster_wheel_link">
    <!-- <selfCollide>true</selfCollide> -->
    <mu1 value="0.0"/>
    <mu2 value="0.0"/>
    <!-- <kp value="100000.0" />
	             <kd value="1.0" /> -->
  </gazebo>
  <gazebo reference="fr_caster_link">
    <!-- <selfCollide>true</selfCollide> -->
    <mu1 value="0.0"/>
    <mu2 value="0.0"/>
    <!-- <kp value="100000.0" />
	             <kd value="1.0" /> -->
  </gazebo>
  <link name="bl_back_wheel_link">
    <mass value="1.2"/>
    <inertial>
      <mass value="1.2"/>
      <inertia ixx="0.000290322" ixy="0.0" ixz="0.0" iyy="0.0006752178025" iyz="0.0" izz="0.0006752178025"/>
    </inertial>
    <visual>
      <origin rpy="0 1.57079632679 0" xyz="0 0 0"/>
      <geometry>
        <cylinder length="0.0381" radius="0.072805"/>
        <!-- <mesh filename="package://talos_description/meshes/wheel/back_wheel.stl" scale="${scale} ${scale} ${scale}" /> -->
      </geometry>
      <material name="white"/>
    </visual>
    <collision>
      <origin rpy="0 1.57079632679 0" xyz="0 0 0"/>
      <geometry>
        <cylinder length="0.0381" radius="0.072805"/>
      </geometry>
    </collision>
  </link>
  <joint name="bl_back_wheel_joint" type="continuous">
    <origin rpy="0 0 0" xyz="0.229125 -0.2 -0.040132"/>
    <child link="bl_back_wheel_link"/>
    <parent link="base_link"/>
    <axis rpy="0 0 0" xyz="1 0 0"/>
    <limit effort="100" velocity="100"/>
    <joint_properties damping="0.0" friction="0.0"/>
  </joint>
  <gazebo reference="bl_back_wheel_link">
    <selfCollide>true</selfCollide>
    <mu1 value="50.0"/>
    <mu2 value="50.0"/>
    <!-- <kp value="100000.0" />
	             <kd value="1.0" />-->
    <!-- <fdir1 value="1 0 0"/> -->
  </gazebo>
  <link name="br_back_wheel_link">
    <mass value="1.2"/>
    <inertial>
      <mass value="1.2"/>
      <inertia ixx="0.000290322" ixy="0.0" ixz="0.0" iyy="0.0006752178025" iyz="0.0" izz="0.0006752178025"/>
    </inertial>
    <visual>
      <origin rpy="0 1.57079632679 0" xyz="0 0 0"/>
      <geometry>
        <cylinder length="0.0381" radius="0.072805"/>
        <!-- <mesh filename="package://talos_description/meshes/wheel/back_wheel.stl" scale="${scale} ${scale} ${scale}" /> -->
      </geometry>
      <material name="white"/>
    </visual>
    <collision>
      <origin rpy="0 1.57079632679 0" xyz="0 0 0"/>
      <geometry>
        <cylinder length="0.0381" radius="0.072805"/>
      </geometry>
    </collision>
  </link>
  <joint name="br_back_wheel_joint" type="continuous">
    <origin rpy="0 0 0" xyz="-0.229125 -0.2 -0.040132"/>
    <child link="br_back_wheel_link"/>
    <parent link="base_link"/>
    <axis rpy="0 0 0" xyz="1 0 0"/>
    <limit effort="100" velocity="100"/>
    <joint_properties damping="0.0" friction="0.0"/>
  </joint>
  <gazebo reference="br_back_wheel_link">
    <selfCollide>true</selfCollide>
    <mu1 value="50.0"/>
    <mu2 value="50.0"/>
    <!-- <kp value="100000.0" />
	             <kd value="1.0" />-->
    <!-- <fdir1 value="1 0 0"/> -->
  </gazebo>
  <xacro:caster_wheel_transmission prefix="fl"/>
  <xacro:caster_wheel_transmission prefix="fr"/>
  <transmission name="br_back_wheel_trans">
    <type>transmission_interface/SimpleTransmission</type>
    <joint name="br_back_wheel_joint">
      <hardwareInterface>VelocityJointInterface</hardwareInterface>
    </joint>
    <actuator name="br_back_wheel_motor">
      <mechanicalReduction>1</mechanicalReduction>
      <hardwareInterface>VelocityJointInterface</hardwareInterface>
    </actuator>
  </transmission>
  <transmission name="bl_back_wheel_trans">
    <type>transmission_interface/SimpleTransmission</type>
    <joint name="bl_back_wheel_joint">
      <hardwareInterface>VelocityJointInterface</hardwareInterface>
    </joint>
    <actuator name="bl_back_wheel_motor">
      <mechanicalReduction>1</mechanicalReduction>
      <hardwareInterface>VelocityJointInterface</hardwareInterface>
    </actuator>
  </transmission>
  <link name="torso_link">
    <visual>
      <origin rpy="0 0 -1.57079632679" xyz="-0.2162 0.2162 -0.33965"/>
      <geometry>
        <mesh filename="package://talos_description/meshes/torso/torso_link.stl" scale="0.001 0.001 0.001"/>
      </geometry>
      <material name="white"/>
    </visual>
    <collision>
      <origin rpy="0 0 0" xyz="0 0 0.51909"/>
      <geometry>
        <box size="0.4324 0.4324 1.03818"/>
      </geometry>
    </collision>
    <inertial>
      <mass value="5.2"/>
      <inertia ixx="0.548074571373" ixy="0.0" ixz="0.0" iyy="0.162040458667" iyz="0.0" izz="0.548074571373"/>
    </inertial>
  </link>
  <joint name="base_to_torso" type="revolute">
    <limit effort="1000.0" lower="-3.14159265359" upper="3.14159265359" velocity="1.0"/>
    <axis xyz="0 0 1"/>
    <parent link="base_link"/>
    <child link="torso_link"/>
    <origin rpy="0 0 3.14159265359" xyz="0 0 0.37817"/>
    <!--<origin xyz="0 0 ${base_height}" rpy="0 0 0"/>-->
  </joint>
  <transmission name="base_to_torso_trans">
    <type>transmission_interface/SimpleTransmission</type>
    <joint name="base_to_torso">
      <hardwareInterface>EffortJointInterface</hardwareInterface>
    </joint>
    <actuator name="base_to_torso_motor">
      <mechanicalReduction>1</mechanicalReduction>
      <hardwareInterface>EffortJointInterface</hardwareInterface>
    </actuator>
  </transmission>
  <link name="arm_shoulder_link">
    <visual>
      <origin rpy="1.57079632679 0 1.57079632679" xyz="-0.053175 -0.035 -0.11"/>
      <geometry>
        <mesh filename="package://talos_description/meshes/arm/shoulder_link.stl" scale="0.001 0.001 0.001"/>
      </geometry>
      <material name="white"/>
    </visual>
    <collision>
      <origin rpy="0 0 0" xyz="0.053175 0.065 0"/>
      <geometry>
        <box size="0.10635 0.2 0.22"/>
      </geometry>
    </collision>
    <inertial>
      <mass value="0.22"/>
      <inertia ixx="0.00109468924583" ixy="0.0" ixz="0.0" iyy="0.000940689245833" iyz="0.0" izz="0.00162066666667"/>
    </inertial>
  </link>
  <link name="arm_upper_arm_link">
    <visual>
      <origin rpy="0 0 1.57079632679" xyz="0.01 -0.075 -0.075"/>
      <geometry>
        <mesh filename="package://talos_description/meshes/arm/upper_arm_link.stl" scale="0.001 0.001 0.001"/>
      </geometry>
      <material name="white"/>
    </visual>
    <collision>
      <origin rpy="0 0 0" xyz="0 0.2 0"/>
      <geometry>
        <box size="0.02 0.55 0.15"/>
      </geometry>
    </collision>
    <inertial>
      <mass value="0.22"/>
      <inertia ixx="0.000419833333333" ixy="0.0" ixz="0.0" iyy="0.00555316666667" iyz="0.0" izz="0.00595833333333"/>
    </inertial>
  </link>
  <link name="arm_elbow_bracket_link">
    <visual>
      <origin rpy="0 0 1.57079632679" xyz="0.03255 0 -0.10365"/>
      <geometry>
        <mesh filename="package://talos_description/meshes/arm/elbow_bracket_link.stl" scale="0.001 0.001 0.001"/>
      </geometry>
      <material name="white"/>
    </visual>
    <collision>
      <origin rpy="0 0 0" xyz="0 0.0755 0"/>
      <geometry>
        <box size="0.0651 0.151 0.2073"/>
      </geometry>
    </collision>
    <inertial>
      <mass value="0.22"/>
      <inertia ixx="0.0008655405" ixy="0.0" ixz="0.0" iyy="0.000495715183333" iyz="0.0" izz="0.00120586198333"/>
    </inertial>
  </link>
  <link name="arm_elbow_block_link">
    <visual>
      <origin rpy="-1.57079632679 0 -1.57079632679" xyz="-0.03176 0.13672 0.097465"/>
      <geometry>
        <mesh filename="package://talos_description/meshes/arm/elbow_block_link.stl" scale="0.001 0.001 0.001"/>
      </geometry>
      <material name="white"/>
    </visual>
    <collision>
      <origin rpy="0 0 0" xyz="0 0.05261 0"/>
      <geometry>
        <box size="0.06352 0.16822 0.19493"/>
      </geometry>
    </collision>
    <inertial>
      <mass value="0.22"/>
      <inertia ixx="0.000770595747167" ixy="0.0" ixz="0.0" iyy="0.000592767244667" iyz="0.0" izz="0.00121542067717"/>
    </inertial>
  </link>
  <link name="arm_lower_arm_link">
    <visual>
      <origin rpy="-1.57079632679 0 -1.57079632679" xyz="-0.015 0.304 0.07"/>
      <geometry>
        <mesh filename="package://talos_description/meshes/arm/lower_arm_link.stl" scale="0.001 0.001 0.001"/>
      </geometry>
      <material name="white"/>
    </visual>
    <collision>
      <origin rpy="0 0 0" xyz="0 0.119 0"/>
      <geometry>
        <box size="0.03 0.37 0.14"/>
      </geometry>
    </collision>
    <inertial>
      <mass value="0.22"/>
      <inertia ixx="0.000375833333333" ixy="0.0" ixz="0.0" iyy="0.00252633333333" iyz="0.0" izz="0.00286916666667"/>
    </inertial>
  </link>
  <link name="arm_wrist_link">
    <visual>
      <origin rpy="-1.57079632679 0 -1.57079632679" xyz="-0.03175 0.06388 0.07"/>
      <geometry>
        <mesh filename="package://talos_description/meshes/arm/wrist_link.stl" scale="0.001 0.001 0.001"/>
      </geometry>
      <material name="white"/>
    </visual>
    <collision>
      <origin rpy="0 0 0" xyz="0 0.02769 0"/>
      <geometry>
        <box size="0.0635 0.07238 0.14"/>
      </geometry>
    </collision>
    <inertial>
      <mass value="0.22"/>
      <inertia ixx="0.000433257916667" ixy="0.0" ixz="0.0" iyy="0.000169970430667" iyz="0.0" izz="0.000455379180667"/>
    </inertial>
  </link>
  <joint name="torso_to_arm_shoulder" type="revolute">
    <limit effort="1000.0" lower="-1.57079632679" upper="0" velocity="1.0"/>
    <axis xyz="0 0 1"/>
    <parent link="torso_link"/>
    <child link="arm_shoulder_link"/>
    <!-- <xacro:insert_block name="origin"/> -->
    <origin rpy="0 0 0" xyz="0.276375 -0.1517 0.81818"/>
  </joint>
  <joint name="arm_shoulder_to_arm_upper_arm" type="revolute">
    <limit effort="1000.0" lower="-0.785398163397" upper="0.785398163397" velocity="1.0"/>
    <axis xyz="1 0 0"/>
    <parent link="arm_shoulder_link"/>
    <child link="arm_upper_arm_link"/>
    <origin rpy="0 0 0" xyz="0 0.095 0"/>
  </joint>
  <joint name="arm_upper_arm_to_arm_elbow_bracket" type="revolute">
    <limit effort="1000.0" lower="-0.785398163397" upper="0.785398163397" velocity="1.0"/>
    <axis xyz="1 0 0"/>
    <parent link="arm_upper_arm_link"/>
    <child link="arm_elbow_bracket_link"/>
    <origin rpy="0 0 0" xyz="0 0.4 0"/>
  </joint>
  <joint name="arm_elbow_bracket_to_arm_elbow_block" type="revolute">
    <limit effort="1000.0" lower="-0.785398163397" upper="0.785398163397" velocity="1.0"/>
    <axis xyz="0 0 1"/>
    <parent link="arm_elbow_bracket_link"/>
    <child link="arm_elbow_block_link"/>
    <origin rpy="0 0 0" xyz="0 0.129 0"/>
  </joint>
  <joint name="arm_elbow_block_to_arm_lower_arm" type="revolute">
    <limit effort="1000.0" lower="-0.785398163397" upper="0.785398163397" velocity="1.0"/>
    <axis xyz="1 0 0"/>
    <parent link="arm_elbow_block_link"/>
    <child link="arm_lower_arm_link"/>
    <origin rpy="0 0 0" xyz="0 0.106 0"/>
  </joint>
  <joint name="arm_lower_arm_to_arm_wrist" type="revolute">
    <limit effort="1000.0" lower="-0.785398163397" upper="0.785398163397" velocity="1.0"/>
    <axis xyz="1 0 0"/>
    <parent link="arm_lower_arm_link"/>
    <child link="arm_wrist_link"/>
    <origin rpy="0 0 0" xyz="0 0.289 0"/>
  </joint>
  <transmission name="torso_to_arm_shoulder_trans">
    <type>transmission_interface/SimpleTransmission</type>
    <joint name="torso_to_arm_shoulder">
      <hardwareInterface>EffortJointInterface</hardwareInterface>
    </joint>
    <actuator name="torso_to_shoulder_motor">
      <mechanicalReduction>1</mechanicalReduction>
      <hardwareInterface>EffortJointInterface</hardwareInterface>
    </actuator>
  </transmission>
  <transmission name="arm_shoulder_to_arm_upper_arm_trans">
    <type>transmission_interface/SimpleTransmission</type>
    <joint name="arm_shoulder_to_arm_upper_arm">
      <hardwareInterface>EffortJointInterface</hardwareInterface>
    </joint>
    <actuator name="arm_shoulder_to_arm_upper_arm_motor">
      <mechanicalReduction>1</mechanicalReduction>
      <hardwareInterface>EffortJointInterface</hardwareInterface>
    </actuator>
  </transmission>
  <transmission name="arm_upper_arm_to_arm_elbow_bracket_trans">
    <type>transmission_interface/SimpleTransmission</type>
    <joint name="arm_upper_arm_to_arm_elbow_bracket">
      <hardwareInterface>EffortJointInterface</hardwareInterface>
    </joint>
    <actuator name="arm_upper_arm_to_arm_elbow_motor">
      <mechanicalReduction>1</mechanicalReduction>
      <hardwareInterface>EffortJointInterface</hardwareInterface>
    </actuator>
  </transmission>
  <transmission name="arm_elbow_bracket_to_arm_elbow_block_trans">
    <type>transmission_interface/SimpleTransmission</type>
    <joint name="arm_elbow_bracket_to_arm_elbow_block">
      <hardwareInterface>EffortJointInterface</hardwareInterface>
    </joint>
    <actuator name="arm_elbow_bracket_to_arm_elbow_block_motor">
      <mechanicalReduction>1</mechanicalReduction>
      <hardwareInterface>EffortJointInterface</hardwareInterface>
    </actuator>
  </transmission>
  <transmission name="arm_elbow_block_to_arm_lower_arm_trans">
    <type>transmission_interface/SimpleTransmission</type>
    <joint name="arm_elbow_block_to_arm_lower_arm">
      <hardwareInterface>EffortJointInterface</hardwareInterface>
    </joint>
    <actuator name="arm_elbow_block_to_arm_lower_arm_motor">
      <mechanicalReduction>1</mechanicalReduction>
      <hardwareInterface>EffortJointInterface</hardwareInterface>
    </actuator>
  </transmission>
  <transmission name="arm_lower_arm_to_arm_wrist_trans">
    <type>transmission_interface/SimpleTransmission</type>
    <joint name="arm_lower_arm_to_arm_wrist">
      <hardwareInterface>EffortJointInterface</hardwareInterface>
    </joint>
    <actuator name="arm_lower_arm_to_arm_wrist_motor">
      <mechanicalReduction>1</mechanicalReduction>
      <hardwareInterface>EffortJointInterface</hardwareInterface>
    </actuator>
  </transmission>
  <link name="gripper_base_link">
    <visual>
      <origin rpy="0 0 0" xyz="-0.04445 0 -0.04445"/>
      <geometry>
        <mesh filename="package://talos_description/meshes/gripper/gripper_base_link.stl" scale="0.001 0.001 0.001"/>
      </geometry>
      <material name="white"/>
    </visual>
    <collision>
      <origin rpy="1.57079632679 0 0" xyz="0 0.04158 0"/>
      <geometry>
        <cylinder length="0.08316" radius="0.04445"/>
      </geometry>
    </collision>
    <inertial>
      <mass value="0.22"/>
      <inertia ixx="0.000289784366667" ixy="0.0" ixz="0.0" iyy="0.000271677919333" iyz="0.0" izz="0.000271677919333"/>
    </inertial>
  </link>
  <link name="gripper_stationary_claw_link">
    <visual>
      <origin rpy="0 -1.57079632679 0" xyz="0.021415 0 -0.0555625"/>
      <geometry>
        <mesh filename="package://talos_description/meshes/gripper/stationary_claw_link.stl" scale="0.001 0.001 0.001"/>
      </geometry>
      <material name="white"/>
    </visual>
    <collision>
      <origin rpy="0 -1.57079632679 0" xyz="0.021415 0 -0.0555625"/>
      <geometry>
        <mesh filename="package://talos_description/meshes/gripper/stationary_claw_link.stl" scale="0.001 0.001 0.001"/>
      </geometry>
    </collision>
    <inertial>
      <mass value="0.22"/>
      <inertia ixx="0.000169855563167" ixy="0.0" ixz="0.0" iyy="0.000420632538333" iyz="0.0" izz="0.000523226441833"/>
    </inertial>
  </link>
  <link name="gripper_movable_claw_link">
    <visual>
      <origin rpy="0 3.14159265359 0" xyz="0.028035 -0.01 0.025"/>
      <geometry>
        <mesh filename="package://talos_description/meshes/gripper/movable_claw_link.stl" scale="0.001 0.001 0.001"/>
      </geometry>
      <material name="white"/>
    </visual>
    <collision>
      <origin rpy="0 3.14159265359 0" xyz="0.028035 -0.01 0.025"/>
      <geometry>
        <mesh filename="package://talos_description/meshes/gripper/movable_claw_link.stl" scale="0.001 0.001 0.001"/>
      </geometry>
    </collision>
    <inertial>
      <mass value="0.22"/>
      <inertia ixx="0.000433257916667" ixy="0.0" ixz="0.0" iyy="0.000169970430667" iyz="0.0" izz="0.000455379180667"/>
    </inertial>
  </link>
  <joint name="arm_wrist_to_gripper_base" type="revolute">
    <limit effort="1000.0" lower="-3.14159265359" upper="3.14159265359" velocity="1.0"/>
    <axis xyz="0 1 0"/>
    <parent link="arm_wrist_link"/>
    <child link="gripper_base_link"/>
    <origin rpy="0 0 0" xyz="0 0.06388 0"/>
    <!--<origin xyz="0 ${wrist_length - wrist_offset} 0" rpy="0 0 0"/>-->
  </joint>
  <joint name="gripper_base_to_stationary_claw" type="fixed">
    <parent link="gripper_base_link"/>
    <child link="gripper_stationary_claw_link"/>
    <origin rpy="0 0 0" xyz="0 0.08316 0"/>
  </joint>
  <joint name="gripper_stationary_claw_to_gripper_movable_claw" type="revolute">
    <limit effort="1000.0" lower="-0.224399475256" upper="0.785398163397" velocity="1.0"/>
    <axis xyz="1 0 0"/>
    <parent link="gripper_stationary_claw_link"/>
    <child link="gripper_movable_claw_link"/>
    <origin rpy="0 0 0" xyz="0 0.041 0.018"/>
  </joint>
  <transmission name="arm_wrist_to_gripper_base_trans">
    <type>transmission_interface/SimpleTransmission</type>
    <joint name="arm_wrist_to_gripper_base">
      <hardwareInterface>EffortJointInterface</hardwareInterface>
    </joint>
    <actuator name="arm_wrist_to_gripper_base_motor">
      <mechanicalReduction>1</mechanicalReduction>
      <hardwareInterface>EffortJointInterface</hardwareInterface>
    </actuator>
  </transmission>
  <transmission name="gripper_stationary_claw_to_gripper_movable_claw_trans">
    <type>transmission_interface/SimpleTransmission</type>
    <joint name="gripper_stationary_claw_to_gripper_movable_claw">
      <hardwareInterface>EffortJointInterface</hardwareInterface>
    </joint>
    <actuator name="gripper_stationary_claw_to_gripper_movable_claw_motor">
      <mechanicalReduction>1</mechanicalReduction>
      <hardwareInterface>EffortJointInterface</hardwareInterface>
    </actuator>
  </transmission>
  <link name="talos_head_link">
    <mass value="0.2"/>
    <inertial>
      <mass value="0.2"/>
      <inertia ixx="9.2592592593e-06" ixy="0.0" ixz="0.0" iyy="9.2592592593e-06" iyz="0.0" izz="9.2592592593e-06"/>
    </inertial>
    <visual>
      <origin rpy="0 0 0" xyz="0 0.075 0"/>
      <geometry>
        <mesh filename="package://talos_description/urdf/head/head.stl" scale="0.001 0.001 0.001"/>
      </geometry>
      <material name="white"/>
    </visual>
    <collision>
      <origin rpy="0 0 0" xyz="0 0 0"/>
      <geometry>
        <mesh filename="package://talos_description/urdf/head/head.stl" scale="0.001 0.001 0.001"/>
      </geometry>
    </collision>
  </link>
  <link name="talos_neck_link">
    <mass value="0.2"/>
    <inertial>
      <mass value="0.2"/>
      <inertia ixx="9.2592592593e-06" ixy="0.0" ixz="0.0" iyy="9.2592592593e-06" iyz="0.0" izz="9.2592592593e-06"/>
    </inertial>
    <visual>
      <origin rpy="0 -0.261799387799 0" xyz="0 0 0"/>
      <geometry>
        <mesh filename="package://talos_description/urdf/head/neck.stl" scale="0.001 0.001 0.001"/>
      </geometry>
      <material name="white"/>
    </visual>
    <collision>
      <origin rpy="0 0 0" xyz="0 0 0"/>
      <geometry>
        <mesh filename="package://talos_description/urdf/head/neck.stl" scale="0.001 0.001 0.001"/>
      </geometry>
    </collision>
  </link>
  <joint name="talos_head_joint" type="fixed">
    <origin rpy="0 0 0" xyz="0 0 0"/>
    <child link="talos_head_link"/>
    <parent link="talos_neck_link"/>
    <axis rpy="0 0 0" xyz="0 1 0"/>
    <!-- <limit effort="100"
                          velocity="100" />
                   <joint_properties damping="0.0"
                                     friction="0.0" /> -->
  </joint>
  <joint name="talos_neck_joint" type="fixed">
    <origin rpy="1.57079632679 0 3.14159265359" xyz="0 0 0.95318"/>
    <child link="talos_neck_link"/>
    <parent link="torso_link"/>
    <axis rpy="0 0 0" xyz="0 1 0"/>
    <!-- <limit effort="100"
                          velocity="100" />
                   <joint_properties damping="0.0"
                                     friction="0.0" /> -->
  </joint>
  <gazebo reference="talos_head_link">
    <selfCollide>true</selfCollide>
  </gazebo>
  <gazebo reference="talos_neck_link">
    <selfCollide>true</selfCollide>
  </gazebo>
</robot>

