<?xml version="1.0" ?>
<!-- =================================================================================== -->
<!-- |    This document was autogenerated by xacro from robot.urdf.xacro               | -->
<!-- |    EDITING THIS FILE BY HAND IS NOT RECOMMENDED                                 | -->
<!-- =================================================================================== -->
<robot name="robot" xmlns:xacro="http://www.ros.org/wiki/xacro">
  <!--X Y-->
  <!-- theirs ours-->
  <!--Z X-->
  <!--Y Z-->
  <link name="base_link">
    <visual>
      <origin rpy="0 0 0" xyz="0 0 0.189085"/>
      <geometry>
        <box size="0.62265 0.62265 0.37817"/>
      </geometry>
      <material name="white">
        <color rgba="1 1 1 1"/>
      </material>
    </visual>
    <collision>
      <origin rpy="0 0 0" xyz="0 0 0.189085"/>
      <geometry>
        <box size="0.62265 0.62265 0.37817"/>
      </geometry>
    </collision>
    <inertial>
      <mass value="0.22"/>
      <inertia ixx="0.00972960214233" ixy="0.0" ixz="0.0" iyy="0.014215410825" iyz="0.0" izz="0.00972960214233"/>
    </inertial>
  </link>
  <link name="body_link">
    <visual>
      <origin rpy="0 0 0" xyz="0 0 0.50159"/>
      <geometry>
        <box size="0.4324 0.4324 1.00318"/>
      </geometry>
      <material name="white">
        <color rgba="1 1 1 1"/>
      </material>
    </visual>
    <collision>
      <origin rpy="0 0 0" xyz="0 0 0.50159"/>
      <geometry>
        <box size="0.4324 0.4324 1.00318"/>
      </geometry>
    </collision>
    <inertial>
      <mass value="0.22"/>
      <inertia ixx="0.0218778976607" ixy="0.0" ixz="0.0" iyy="0.00685555786667" iyz="0.0" izz="0.0218778976607"/>
    </inertial>
  </link>
  <link name="shoulder_link">
    <visual>
      <origin rpy="1.570795 0 1.570795" xyz="0 -0.035 -0.11"/>
      <geometry>
        <mesh filename="package://rviztest/meshes/shoulder_link.stl" scale="0.001 0.001 0.001"/>
      </geometry>
      <material name="white">
        <color rgba="1 1 1 1"/>
      </material>
    </visual>
    <collision>
      <origin rpy="0 0 0" xyz="0.053175 0.065 0"/>
      <geometry>
        <box size="0.10635 0.2 0.22"/>
      </geometry>
    </collision>
    <inertial>
      <mass value="0.22"/>
      <inertia ixx="0.00109468924583" ixy="0.0" ixz="0.0" iyy="0.000940689245833" iyz="0.0" izz="0.00162066666667"/>
    </inertial>
  </link>
  <link name="upper_arm_link">
    <visual>
      <origin rpy="0 0 1.570795" xyz="0.01 -0.075 -0.075"/>
      <geometry>
        <mesh filename="package://rviztest/meshes/upper_arm_link.stl" scale="0.001 0.001 0.001"/>
      </geometry>
      <material name="white">
        <color rgba="1 1 1 1"/>
      </material>
    </visual>
    <collision>
      <origin rpy="0 0 0" xyz="0 0.2 0"/>
      <geometry>
        <box size="0.02 0.55 0.15"/>
      </geometry>
    </collision>
    <inertial>
      <mass value="0.22"/>
      <inertia ixx="0.000419833333333" ixy="0.0" ixz="0.0" iyy="0.00555316666667" iyz="0.0" izz="0.00595833333333"/>
    </inertial>
  </link>
  <link name="elbow_bracket_link">
    <visual>
      <origin rpy="0 0 1.570795" xyz="0.03255 0 -0.10365"/>
      <geometry>
        <mesh filename="package://rviztest/meshes/elbow_bracket_link.stl" scale="0.001 0.001 0.001"/>
      </geometry>
      <material name="white">
        <color rgba="1 1 1 1"/>
      </material>
    </visual>
    <collision>
      <origin rpy="0 0 0" xyz="0 0.0755 0"/>
      <geometry>
        <box size="0.0651 0.151 0.2073"/>
      </geometry>
    </collision>
    <inertial>
      <mass value="0.22"/>
      <inertia ixx="0.0008655405" ixy="0.0" ixz="0.0" iyy="0.000495715183333" iyz="0.0" izz="0.00120586198333"/>
    </inertial>
  </link>
  <link name="elbow_block_link">
    <visual>
      <origin rpy="1.570795 0 -1.570795" xyz="0.03176 0.129 -0.097465"/>
      <geometry>
        <mesh filename="package://rviztest/meshes/elbow_block_link.stl" scale="0.001 0.001 0.001"/>
      </geometry>
      <material name="white">
        <color rgba="1 1 1 1"/>
      </material>
    </visual>
    <collision>
      <origin rpy="0 0 0" xyz="0 0.05261 0"/>
      <geometry>
        <box size="0.06352 0.16822 0.19493"/>
      </geometry>
    </collision>
    <inertial>
      <mass value="0.22"/>
      <inertia ixx="0.000770595747167" ixy="0.0" ixz="0.0" iyy="0.000592767244667" iyz="0.0" izz="0.00121542067717"/>
    </inertial>
  </link>
  <link name="lower_arm_link">
    <visual>
      <origin rpy="1.570795 0 1.570795" xyz="-0.03175 -0.06719 -0.288533"/>
      <geometry>
        <mesh filename="package://rviztest/meshes/lower_arm_link.stl" scale="0.001 0.001 0.001"/>
      </geometry>
      <material name="white">
        <color rgba="1 1 1 1"/>
      </material>
    </visual>
    <collision>
      <origin rpy="0 0 0" xyz="0 0.138905 0"/>
      <geometry>
        <box size="0.0635 0.41219 0.14"/>
      </geometry>
    </collision>
    <inertial>
      <mass value="0.22"/>
      <inertia ixx="0.000433257916667" ixy="0.0" ixz="0.0" iyy="0.00318876884517" iyz="0.0" izz="0.00347417759517"/>
    </inertial>
  </link>
  <joint name="base_to_body" type="revolute">
    <limit effort="1000.0" lower="-3.14159" upper="3.14159" velocity="1.0"/>
    <axis xyz="0 0 1"/>
    <parent link="base_link"/>
    <child link="body_link"/>
    <origin rpy="0 0 0" xyz="0 0 0.37817"/>
  </joint>
  <joint name="body_to_shoulder" type="revolute">
    <limit effort="1000.0" lower="-1.570795" upper="0" velocity="1.0"/>
    <axis xyz="0 0 1"/>
    <parent link="body_link"/>
    <child link="shoulder_link"/>
    <origin rpy="0 0 0" xyz="0.2162 0 0.89318"/>
  </joint>
  <joint name="shoulder_to_upper_arm" type="revolute">
    <limit effort="1000.0" lower="-0.7853975" upper="0.7853975" velocity="1.0"/>
    <axis xyz="1 0 0"/>
    <parent link="shoulder_link"/>
    <child link="upper_arm_link"/>
    <origin rpy="0 0 0" xyz="0.053175 0.095 0"/>
  </joint>
  <joint name="upper_arm_to_elbow_bracket" type="revolute">
    <limit effort="1000.0" lower="-0.7853975" upper="0.7853975" velocity="1.0"/>
    <axis xyz="1 0 0"/>
    <parent link="upper_arm_link"/>
    <child link="elbow_bracket_link"/>
    <origin rpy="0 0 0" xyz="0 0.4 0"/>
  </joint>
  <joint name="elbow_bracket_to_elbow_block" type="revolute">
    <limit effort="1000.0" lower="-0.7853975" upper="0.7853975" velocity="1.0"/>
    <axis xyz="0 0 1"/>
    <parent link="elbow_bracket_link"/>
    <child link="elbow_block_link"/>
    <origin rpy="0 0 0" xyz="0 0.129 0"/>
  </joint>
  <joint name="elbow_block_to_lower_arm" type="revolute">
    <limit effort="1000.0" lower="-0.7853975" upper="0.7853975" velocity="1.0"/>
    <axis xyz="1 0 0"/>
    <parent link="elbow_block_link"/>
    <child link="lower_arm_link"/>
    <origin rpy="0 0 0" xyz="0 0.106 0"/>
  </joint>
</robot>

